Workbook

Sheet RABONA PAYMENTS
N2: =290.79-123 -> 167.79 | AD2: REIMBURSE FROM / PRORATE TO
N3: REPORT | O3: JANUARY 2026 | AG3: REIMBURSEMENT OF EXPENSES TO EMPLOYEES | AH3: PERSONAL EXPENSES PAID BY COMPANY
C4: 26/1/
Z5: SHARE HOLDER | AA5: REIMBURSE | AD5: REIMBURSE | AE5: REIMBURSE | AG5: CASH | AH5: SHARE HOLDER
B6: REF. NO: MONTH RECEIVED | C6: REF. NO. MONTH PAID | D6: REF. NO: MONTH PAID | E6: ACCOUNT PAID FROM | F6: INWARDS/ OUTWARDS | G6: EXPENSE OF | H6: REF. NO: Travel exp. | I6: REF. NO: Exp. Reimb. | J6: REF. NO: Salaries | K6: INWARDS TRANSFER REFERENCE | L6: INVOICE DATE | M6: MONTH ISSUED | N6: COMPANY | O6: ITEM | P6: SUBCATEGORY | Q6: CATEGORY | R6: TOTAL AMOUNT foreign currency | S6: TOTAL AMOUNT (EURO) | T6: AMOUNT PAID | U6: AMOUNT RECEIVED | V6: DATE PAID / DATE RECEIVED …. | W6: MONTH PAYED | X6: TOTAL PAID (EURO) | Y6: BALANCE (EURO) | Z6: PAYMENT TYPE …. | AA6: EXPENSE OF …. | AB6: STATUS | AC6: COMMENTS …. | AD6: REIMBURSE FROM/ PRORATE TO | AE6: TOTAL AMOUNT (EURO) | AF6: INVOICE NUMBER | AG6: TOTAL AMOUNT Incl. VAT (EURO) | AH6: AMOUNT | AI6: EXPENSES PAID IN CASH BY
B7: 25/7/3 | E7: CURRENT A/C | F7: OUT | G7: RABONA | J7: S7/3 | L7: 45839 | M7: =L7 -> 45839 | N7: SOCIAL INSURANCE | O7: JUNE 2025 | P7: SOCIAL INSURANCE | Q7: COST OF LABOR | S7: 671.25 | U7: 0 | W7: =V7 -> 0 | X7: =T7+U7 -> 0 | Y7: =S7-X7 -> 671.25 | Z7: BT | AA7: RABONA | AB7: =IF(Y7>0,"PENDING EXECUTION","COMPLETED") -> PENDING EXECUTION | AE7: =IF(AA7=$AD$5,S7,0) -> 0 | AG7: =IF(Z7=$AG$5,X7,0) -> 0 | AH7: =IF(AA7=$AH$5,X7,0) -> 0
B8: 25/8/3 | E8: CURRENT A/C | F8: OUT | G8: RABONA | J8: S8/3 | L8: 45870 | M8: =L8 -> 45870 | N8: SOCIAL INSURANCE | O8: JULY 2025 | P8: SOCIAL INSURANCE | Q8: COST OF LABOR | S8: 671.25 | U8: 0 | W8: =V8 -> 0 | X8: =T8+U8 -> 0 | Y8: =S8-X8 -> 671.25 | Z8: BT | AA8: =G8 -> RABONA | AB8: =IF(Y8>0,"PENDING EXECUTION","COMPLETED") -> PENDING EXECUTION | AE8: =IF(AA8=$AD$5,S8,0) -> 0 | AG8: =IF(Z8=$AG$5,X8,0) -> 0 | AH8: =IF(AA8=$AH$5,X8,0) -> 0
B9: 25/9/3 | E9: CURRENT A/C | F9: OUT | G9: RABONA | J9: S9/3 | L9: 45901 | M9: =L9 -> 45901 | N9: SOCIAL INSURANCE | O9: AUGUST 2025 | P9: SOCIAL INSURANCE | Q9: COST OF LABOR | S9: 671.25 | U9: 0 | W9: =V9 -> 0 | X9: =T9+U9 -> 0 | Y9: =S9-X9 -> 671.25 | Z9: BT | AA9: =G9 -> RABONA | AB9: =IF(Y9>0,"PENDING EXECUTION","COMPLETED") -> PENDING EXECUTION | AE9: =IF(AA9=$AD$5,S9,0) -> 0 | AG9: =IF(Z9=$AG$5,X9,0) -> 0 | AH9: =IF(AA9=$AH$5,X9,0) -> 0
B10: 25/10/3 | E10: CURRENT A/C | F10: OUT | G10: RABONA | J10: S10/3 | L10: 45931 | M10: =L10 -> 45931 | N10: SOCIAL INSURANCE | O10: SEPTEMBER 2025 | P10: SOCIAL INSURANCE | Q10: COST OF LABOR | S10: 671.25 | U10: 0 | W10: =V10 -> 0 | X10: =T10+U10 -> 0 | Y10: =S10-X10 -> 671.25 | Z10: BT | AA10: =G10 -> RABONA | AB10: =IF(Y10>0,"PENDING EXECUTION","COMPLETED") -> PENDING EXECUTION | AE10: =IF(AA10=$AD$5,S10,0) -> 0 | AG10: =IF(Z10=$AG$5,X10,0) -> 0 | AH10: =IF(AA10=$AH$5,X10,0) -> 0
B11: 25/11/1 | E11: CURRENT A/C | F11: OUT | G11: RABONA | J11: S11/1 | L11: 45962 | M11: =L11 -> 45962 | N11: BETIJA KEDEM | O11: B.KEDEM SALARY NOVEMBER 2025 | P11: SALARY BK | Q11: COST OF LABOR | S11: 2142.75 | T11: 2142.75 | U11: 0 | V11: 46030 | W11: =V11 -> 46030 | X11: =T11+U11 -> 2142.75 | Y11: =S11-X11 -> 0 | Z11: BT | AA11: =G11 -> RABONA | AB11: =IF(Y11>0,"PENDING EXECUTION","COMPLETED") -> COMPLETED | AE11: =IF(AA11=$AD$5,S11,0) -> 0 | AG11: =IF(Z11=$AG$5,X11,0) -> 0 | AH11: =IF(AA11=$AH$5,X11,0) -> 0
B12: 25/11/3 | E12: CURRENT A/C | F12: OUT | G12: RABONA | J12: S11/3 | L12: 45962 | M12: =L12 -> 45962 | N12: SOCIAL INSURANCE | O12: OCTOBER 2025 | P12: SOCIAL INSURANCE | Q12: COST OF LABOR | S12: 671.25 | U12: 0 | W12: =V12 -> 0 | X12: =T12+U12 -> 0 | Y12: =S12-X12 -> 671.25 | Z12: BT | AA12: =G12 -> RABONA | AB12: =IF(Y12>0,"PENDING EXECUTION","COMPLETED") -> PENDING EXECUTION | AE12: =IF(AA12=$AD$5,S12,0) -> 0 | AG12: =IF(Z12=$AG$5,X12,0) -> 0 | AH12: =IF(AA12=$AH$5,X12,0) -> 0
B13: 25/12/1 | E13: CURRENT A/C | F13: OUT | G13: RABONA | J13: S12/1 | L13: 45992 | M13: =L13 -> 45992 | N13: BETIJA KEDEM | O13: B.KEDEM SALARY DECEMBER 2025 | P13: SALARY BK | Q13: COST OF LABOR | S13: 2142.75 | U13: 0 | W13: =V13 -> 0 | X13: =T13+U13 -> 0 | Y13: =S13-X13 -> 2142.75 | Z13: BT | AA13: =G13 -> RABONA | AB13: =IF(Y13>0,"PENDING EXECUTION","COMPLETED") -> PENDING EXECUTION | AE13: =IF(AA13=$AD$5,S13,0) -> 0 | AG13: =IF(Z13=$AG$5,X13,0) -> 0 | AH13: =IF(AA13=$AH$5,X13,0) -> 0
B14: 25/12/2 | E14: CURRENT A/C | F14: OUT | G14: RABONA | J14: S12/2 | L14: 45992 | M14: =L14 -> 45992 | N14: PAYE | O14: NOVEMBER 2025 | P14: PAYE | Q14: COST OF LABOR | S14: 71 | U14: 0 | W14: =V14 -> 0 | X14: =T14+U14 -> 0 | Y14: =S14-X14 -> 71 | Z14: BT | AA14: =G14 -> RABONA | AB14: =IF(Y14>0,"PENDING EXECUTION","COMPLETED") -> PENDING EXECUTION | AE14: =IF(AA14=$AD$5,S14,0) -> 0 | AG14: =IF(Z14=$AG$5,X14,0) -> 0 | AH14: =IF(AA14=$AH$5,X14,0) -> 0
B15: 25/12/3 | E15: CURRENT A/C | F15: OUT | G15: RABONA | J15: S12/3 | L15: 45992 | M15: =L15 -> 45992 | N15: SOCIAL INSURANCE | O15: NOVEMBER 2025 | P15: SOCIAL INSURANCE | Q15: COST OF LABOR | S15: 671.25 | U15: 0 | W15: =V15 -> 0 | X15: =T15+U15 -> 0 | Y15: =S15-X15 -> 671.25 | Z15: BT | AA15: =G15 -> RABONA | AB15: =IF(Y15>0,"PENDING EXECUTION","COMPLETED") -> PENDING EXECUTION | AE15: =IF(AA15=$AD$5,S15,0) -> 0 | AG15: =IF(Z15=$AG$5,X15,0) -> 0 | AH15: =IF(AA15=$AH$5,X15,0) -> 0
C16: =IF(A7=0,$C$4,"-") -> 26/1/ | D16: 1 | E16: CURRENT A/C | F16: OUT | G16: RABONA | J16: S1/1 | L16: 46023 | M16: =L16 -> 46023 | N16: BETIJA KEDEM | O16: B.KEDEM SALARY JANUARY 2026 | P16: SALARY BK | Q16: COST OF LABOR | S16: 2142.75 | U16: 0 | W16: =V16 -> 0 | X16: =T16+U16 -> 0 | Y16: =S16-X16 -> 2142.75 | Z16: BT | AA16: =G16 -> RABONA | AB16: =IF(Y16>0,"PENDING EXECUTION","COMPLETED") -> PENDING EXECUTION | AE16: =IF(AA16=$AD$5,S16,0) -> 0 | AG16: =IF(Z16=$AG$5,X16,0) -> 0 | AH16: =IF(AA16=$AH$5,X16,0) -> 0
C17: =IF(A8=0,$C$4,"-") -> 26/1/ | D17: 2 | E17: CURRENT A/C | F17: OUT | G17: RABONA | J17: S1/2 | L17: 46023 | M17: =L17 -> 46023 | N17: PAYE | O17: DECEMBER 2025 | P17: PAYE | Q17: COST OF LABOR | S17: 71 | U17: 0 | W17: =V17 -> 0 | X17: =T17+U17 -> 0 | Y17: =S17-X17 -> 71 | Z17: BT | AA17: =G17 -> RABONA | AB17: =IF(Y17>0,"PENDING EXECUTION","COMPLETED") -> PENDING EXECUTION | AE17: =IF(AA17=$AD$5,S17,0) -> 0 | AG17: =IF(Z17=$AG$5,X17,0) -> 0 | AH17: =IF(AA17=$AH$5,X17,0) -> 0
C18: =IF(A9=0,$C$4,"-") -> 26/1/ | D18: 3 | E18: CURRENT A/C | F18: OUT | G18: RABONA | J18: S1/3 | L18: 46023 | M18: =L18 -> 46023 | N18: SOCIAL INSURANCE | O18: DECEMBER 2025 | P18: SOCIAL INSURANCE | Q18: COST OF LABOR | S18: 671.25 | U18: 0 | W18: =V18 -> 0 | X18: =T18+U18 -> 0 | Y18: =S18-X18 -> 671.25 | Z18: BT | AA18: =G18 -> RABONA | AB18: =IF(Y18>0,"PENDING EXECUTION","COMPLETED") -> PENDING EXECUTION | AE18: =IF(AA18=$AD$5,S18,0) -> 0 | AG18: =IF(Z18=$AG$5,X18,0) -> 0 | AH18: =IF(AA18=$AH$5,X18,0) -> 0
C19: =IF(A8=0,$C$4,"-") -> 26/1/ | D19: 4 | E19: CURRENT A/C | F19: IN | G19: RABONA | K19: A | L19: 46020 | M19: =L19 -> 46020 | N19: INWARDS TRANSFER FROM SUNDAY LIFESTILE SLU INV NO 2025/12/004 | O19: CONSULTING SERVICES for project KYPSELI DECEBER FEE 2025 | P19: CONSULTING SERVICES | Q19: REVENUE | S19: 6000 | U19: =S19 -> 6000 | V19: 46029 | W19: =V19 -> 46029 | X19: =T19+U19 -> 6000 | Y19: =S19-X19 -> 0 | Z19: BT | AA19: =G19 -> RABONA | AB19: =IF(Y19>0,"PENDING EXECUTION","COMPLETED") -> COMPLETED | AC19: INWARDS TRANSFER | AE19: =IF(AA19=$AD$5,S19,0) -> 0 | AG19: =IF(Z19=$AG$5,X19,0) -> 0 | AH19: =IF(AA19=$AH$5,X19,0) -> 0
C20: =IF(A19=0,$C$4,"-") -> 26/1/ | D20: 5 | E20: CURRENT A/C | F20: IN | G20: RABONA | K20: B | L20: 46020 | M20: =L20 -> 46020 | N20: INWARDS TRANSFER FROM OZ SHLOMI SINGLE MEMBER S.A.INV. NO: 2025/12/005 | O20: CONSULTING SERVICES for project GREEN FIELD HOTEL DECEMBER FEE 2025 | P20: CONSULTING SERVICES | Q20: REVENUE | S20: 3500 | U20: =S20 -> 3500 | V20: 46041 | W20: =V20 -> 46041 | X20: =T20+U20 -> 3500 | Y20: =S20-X20 -> 0 | Z20: BT | AA20: =G20 -> RABONA | AB20: =IF(Y20>0,"PENDING EXECUTION","COMPLETED") -> COMPLETED | AC20: INWARDS TRANSFER | AE20: =IF(AA20=$AD$5,S20,0) -> 0 | AG20: =IF(Z20=$AG$5,X20,0) -> 0 | AH20: =IF(AA20=$AH$5,X20,0) -> 0
C21: =IF(A20=0,$C$4,"-") -> 26/1/ | D21: 6 | E21: CURRENT A/C | F21: IN | G21: RABONA | K21: C | L21: 46029 | M21: =L21 -> 46029 | N21: YORAM KEDEM | O21: INVESTMENT FROM SHARE HOLDER | P21: BANK TRANSFERS/CASH DEPOSITS (YK) | Q21: INVESTMENT (SHARE HOLDER'S ACCOUNT) | S21: 8100 | U21: =S21 -> 8100 | V21: 46029 | W21: =V21 -> 46029 | X21: =T21+U21 -> 8100 | Y21: =S21-X21 -> 0 | Z21: CASH | AA21: =G21 -> RABONA | AB21: =IF(Y21>0,"PENDING EXECUTION","COMPLETED") -> COMPLETED | AC21: INWARDS TRANSFER | AE21: =IF(AA21=$AD$5,S21,0) -> 0 | AG21: =IF(Z21=$AG$5,X21,0) -> 8100 | AH21: =IF(AA21=$AH$5,X21,0) -> 0 | AI21: EXPENSES PAID CASH YK
C22: =IF(A21=0,$C$4,"-") -> 26/1/ | D22: 7 | E22: CURRENT A/C | F22: IN | G22: RABONA | K22: D | L22: 46048 | M22: =L22 -> 46048 | N22: INWARDS TRANSFER FROM BTS REAL ESTATE INV. NO: 2026/01/002 | O22: project BLUE LAGOON FIXED EXPENSES JANUARY FIXED EXPENSES 2026 | P22: REIMBURSMENT OF PROCURE AND RUNNING EXPENSES | Q22: REVENUE | S22: 1200 | U22: =S22 -> 1200 | V22: 46052 | W22: =V22 -> 46052 | X22: =T22+U22 -> 1200 | Y22: =S22-X22 -> 0 | Z22: BT | AA22: =G22 -> RABONA | AB22: =IF(Y22>0,"PENDING EXECUTION","COMPLETED") -> COMPLETED | AC22: INWARDS TRANSFER | AE22: =IF(AA22=$AD$5,S22,0) -> 0 | AG22: =IF(Z22=$AG$5,X22,0) -> 0 | AH22: =IF(AA22=$AH$5,X22,0) -> 0
C23: =IF(A22=0,$C$4,"-") -> 26/1/ | D23: 8 | E23: CURRENT A/C | F23: IN | G23: RABONA | K23: E | L23: 46048 | M23: =L23 -> 46048 | N23: INWARDS TRANSFER FROM BTS REAL ESTATE INV. NO: 2026/01/001 | O23: CONSULTING SERVICES for project BLUE LAGOON JANUARY FEES 2026 | P23: CONSULTING SERVICES | Q23: REVENUE | S23: 5000 | U23: =S23 -> 5000 | V23: 46052 | W23: =V23 -> 46052 | X23: =T23+U23 -> 5000 | Y23: =S23-X23 -> 0 | Z23: BT | AA23: =G23 -> RABONA | AB23: =IF(Y23>0,"PENDING EXECUTION","COMPLETED") -> COMPLETED | AC23: INWARDS TRANSFER | AE23: =IF(AA23=$AD$5,S23,0) -> 0 | AG23: =IF(Z23=$AG$5,X23,0) -> 0 | AH23: =IF(AA23=$AH$5,X23,0) -> 0
C24: =IF(A23=0,$C$4,"-") -> 26/1/ | D24: 9 | E24: CURRENT A/C | F24: IN | G24: RABONA | K24: F | L24: 46048 | M24: =L24 -> 46048 | N24: INWARDS TRANSFER FROM EVIMER LTD INV. NO: 2026/01/003 | O24: CONSULTING SERVICES for project URBAN CITY JANUARY 2026 | P24: CONSULTING SERVICES | Q24: REVENUE | S24: 11900 | U24: =S24 -> 11900 | V24: 46052 | W24: =V24 -> 46052 | X24: =T24+U24 -> 11900 | Y24: =S24-X24 -> 0 | Z24: BT | AA24: =G24 -> RABONA | AB24: =IF(Y24>0,"PENDING EXECUTION","COMPLETED") -> COMPLETED | AC24: INWARDS TRANSFER | AE24: =IF(AA24=$AD$5,S24,0) -> 0 | AG24: =IF(Z24=$AG$5,X24,0) -> 0 | AH24: =IF(AA24=$AH$5,X24,0) -> 0
C25: =IF(A24=0,$C$4,"-") -> 26/1/ | D25: 10 | E25: CURRENT A/C | F25: IN | G25: RABONA | K25: G | L25: 46048 | M25: =L25 -> 46048 | N25: INWARDS TRANSFER FROM EVIMER LTD INV. NO: 2026/01/006 | O25: REIMBURSMENTS OF EXPENSES project URBAN CITY NOVEMBER 2025 | P25: REIMBURSMENT OF PROCURE AND RUNNING EXPENSES | Q25: REVENUE | S25: 729 | U25: =S25 -> 729 | V25: 46052 | W25: =V25 -> 46052 | X25: =T25+U25 -> 729 | Y25: =S25-X25 -> 0 | Z25: BT | AA25: =G25 -> RABONA | AB25: =IF(Y25>0,"PENDING EXECUTION","COMPLETED") -> COMPLETED | AC25: INWARDS TRANSFER | AE25: =IF(AA25=$AD$5,S25,0) -> 0 | AG25: =IF(Z25=$AG$5,X25,0) -> 0 | AH25: =IF(AA25=$AH$5,X25,0) -> 0
C26: =IF(A25=0,$C$4,"-") -> 26/1/ | D26: 11 | E26: CURRENT A/C | F26: IN | G26: RABONA | K26: H | L26: 46048 | M26: =L26 -> 46048 | N26: INWARDS TRANSFER FROM OZ SHLOMI SINGLE MEMBER S.A.INV. NO: 2026/01/005 | O26: CONSULTING SERVICES for project GREEN FIELD HOTEL JANUARY FEE 2026 | P26: CONSULTING SERVICES | Q26: REVENUE | S26: 3500 | U26: =S26 -> 3500 | V26: 46052 | W26: =V26 -> 46052 | X26: =T26+U26 -> 3500 | Y26: =S26-X26 -> 0 | Z26: BT | AA26: =G26 -> RABONA | AB26: =IF(Y26>0,"PENDING EXECUTION","COMPLETED") -> COMPLETED | AC26: INWARDS TRANSFER | AE26: =IF(AA26=$AD$5,S26,0) -> 0 | AG26: =IF(Z26=$AG$5,X26,0) -> 0 | AH26: =IF(AA26=$AH$5,X26,0) -> 0
C27: =IF(A26=0,$C$4,"-") -> 26/1/ | D27: 12 | E27: MASTER CARD A/C | F27: IN | G27: RABONA | K27: I | L27: 46052 | M27: =L27 -> 46052 | N27: RABONA | O27: TRANSFER FROM RABONA CURRENT A/S TO RABONA MASTER CARD A/C | P27: MOVEMENT FROM CURRENT A/C TO MASTER CARD A/C | Q27: MOVEMENT FROM CURRENT A/C TO MASTER CARD A/C | S27: 1500 | U27: 0 | V27: 46052 | W27: =V27 -> 46052 | X27: =T27+U27 -> 0 | Y27: =S27-X27 -> 1500 | Z27: BT | AA27: =G27 -> RABONA | AB27: =IF(Y27>0,"PENDING EXECUTION","COMPLETED") -> PENDING EXECUTION | AC27: MOVEMENT BETWEEN A/C | AE27: =IF(AA27=$AD$5,S27,0) -> 0 | AG27: =IF(Z27=$AG$5,X27,0) -> 0 | AH27: =IF(AA27=$AH$5,X27,0) -> 0
C28: =IF(A27=0,$C$4,"-") -> 26/1/ | D28: 13 | E28: MASTER CARD A/C | F28: IN | G28: RABONA | K28: J | L28: 46052 | M28: =L28 -> 46052 | N28: RABONA | O28: TRANSFER FROM RABONA CURRENT A/S TO RABONA MASTER CARD A/C | P28: MOVEMENT FROM CURRENT A/C TO MASTER CARD A/C | Q28: MOVEMENT FROM CURRENT A/C TO MASTER CARD A/C | S28: 1000 | U28: 0 | V28: 46052 | W28: =V28 -> 46052 | X28: =T28+U28 -> 0 | Y28: =S28-X28 -> 1000 | Z28: BT | AA28: =G28 -> RABONA | AB28: =IF(Y28>0,"PENDING EXECUTION","COMPLETED") -> PENDING EXECUTION | AC28: MOVEMENT BETWEEN A/C | AE28: =IF(AA28=$AD$5,S28,0) -> 0 | AG28: =IF(Z28=$AG$5,X28,0) -> 0 | AH28: =IF(AA28=$AH$5,X28,0) -> 0
C29: =IF(A28=0,$C$4,"-") -> 26/1/ | D29: 14 | E29: MASTER CARD A/C | F29: IN | G29: RABONA | K29: K | L29: 46023 | M29: =L29 -> 46023 | N29: RABONA | O29: TRANSFER FROM RABONA CURRENT A/S TO RABONA MASTER CARD A/C | P29: MOVEMENT FROM CURRENT A/C TO MASTER CARD A/C | Q29: MOVEMENT FROM CURRENT A/C TO MASTER CARD A/C | S29: 1000 | U29: 0 | V29: 46052 | W29: =V29 -> 46052 | X29: =T29+U29 -> 0 | Y29: =S29-X29 -> 1000 | Z29: BT | AA29: =G29 -> RABONA | AB29: =IF(Y29>0,"PENDING EXECUTION","COMPLETED") -> PENDING EXECUTION | AC29: MOVEMENT BETWEEN A/C | AE29: =IF(AA29=$AD$5,S29,0) -> 0 | AG29: =IF(Z29=$AG$5,X29,0) -> 0 | AH29: =IF(AA29=$AH$5,X29,0) -> 0
C30: =IF(A29=0,$C$4,"-") -> 26/1/ | D30: 15 | E30: MASTER CARD A/C | F30: IN | G30: RABONA | K30: L | L30: 46026 | M30: =L30 -> 46026 | N30: RABONA | O30: TRANSFER FROM RABONA CURRENT A/S TO RABONA MASTER CARD A/C | P30: MOVEMENT FROM CURRENT A/C TO MASTER CARD A/C | Q30: MOVEMENT FROM CURRENT A/C TO MASTER CARD A/C | S30: 1000 | U30: 0 | V30: 46052 | W30: =V30 -> 46052 | X30: =T30+U30 -> 0 | Y30: =S30-X30 -> 1000 | Z30: BT | AA30: =G30 -> RABONA | AB30: =IF(Y30>0,"PENDING EXECUTION","COMPLETED") -> PENDING EXECUTION | AC30: MOVEMENT BETWEEN A/C | AE30: =IF(AA30=$AD$5,S30,0) -> 0 | AG30: =IF(Z30=$AG$5,X30,0) -> 0 | AH30: =IF(AA30=$AH$5,X30,0) -> 0
C31: =IF(A30=0,$C$4,"-") -> 26/1/ | D31: 16 | E31: CURRENT A/C | F31: IN | G31: RABONA | K31: M | L31: 46035 | M31: =L31 -> 46035 | N31: INWARDS TRANSFER FROM SHA (YORAM KEDEM) | O31: INVESTMENT FROM SHARE HOLDER | P31: BANK TRANSFERS/CASH DEPOSITS (YK) | Q31: INVESTMENT (SHARE HOLDER'S ACCOUNT) | S31: 150 | U31: =S31 -> 150 | V31: =L31 -> 46035 | W31: =V31 -> 46035 | X31: =T31+U31 -> 150 | Y31: =S31-X31 -> 0 | Z31: CASH | AA31: =G31 -> RABONA | AB31: =IF(Y31>0,"PENDING EXECUTION","COMPLETED") -> COMPLETED | AC31: INWARDS TRANSFER | AE31: =IF(AA31=$AD$5,S31,0) -> 0 | AG31: =IF(Z31=$AG$5,X31,0) -> 150 | AH31: =IF(AA31=$AH$5,X31,0) -> 0 | AI31: EXPENSES PAID CASH YK
C32: =IF(A31=0,$C$4,"-") -> 26/1/ | D32: 17 | E32: CURRENT A/C | F32: IN | G32: RABONA | K32: N | L32: 46035 | M32: =L32 -> 46035 | N32: INWARDS TRANSFER FROM SHA (YORAM KEDEM) | O32: INVESTMENT FROM SHARE HOLDER | P32: BANK TRANSFERS/CASH DEPOSITS (YK) | Q32: INVESTMENT (SHARE HOLDER'S ACCOUNT) | S32: 200 | U32: =S32 -> 200 | V32: =L32 -> 46035 | W32: =V32 -> 46035 | X32: =T32+U32 -> 200 | Y32: =S32-X32 -> 0 | Z32: CASH | AA32: =G32 -> RABONA | AB32: =IF(Y32>0,"PENDING EXECUTION","COMPLETED") -> COMPLETED | AC32: INWARDS TRANSFER | AE32: =IF(AA32=$AD$5,S32,0) -> 0 | AG32: =IF(Z32=$AG$5,X32,0) -> 200 | AH32: =IF(AA32=$AH$5,X32,0) -> 0 | AI32: EXPENSES PAID CASH YK
C33: =IF(A32=0,$C$4,"-") -> 26/1/ | D33: 18 | E33: MASTER CARD A/C | F33: IN | G33: RABONA | K33: O | L33: 46030 | M33: =L33 -> 46030 | N33: RABONA | O33: TRANSFER FROM RABONA CURRENT A/S TO RABONA MASTER CARD A/C | P33: MOVEMENT FROM CURRENT A/C TO MASTER CARD A/C | Q33: MOVEMENT FROM CURRENT A/C TO MASTER CARD A/C | S33: 2000 | U33: 0 | V33: 46030 | W33: =V33 -> 46030 | X33: =T33+U33 -> 0 | Y33: =S33-X33 -> 2000 | Z33: BT | AA33: =G33 -> RABONA | AB33: =IF(Y33>0,"PENDING EXECUTION","COMPLETED") -> PENDING EXECUTION | AC33: MOVEMENT BETWEEN A/C | AE33: =IF(AA33=$AD$5,S33,0) -> 0 | AG33: =IF(Z33=$AG$5,X33,0) -> 0 | AH33: =IF(AA33=$AH$5,X33,0) -> 0
C34: =IF(A33=0,$C$4,"-") -> 26/1/ | D34: 19 | E34: CURRENT A/C | F34: IN | G34: RABONA | K34: P | L34: 46041 | M34: =L34 -> 46041 | N34: YORAM KEDEM | O34: INVESTMENT FROM SHARE HOLDER | P34: BANK TRANSFERS/CASH DEPOSITS (YK) | Q34: INVESTMENT (SHARE HOLDER'S ACCOUNT) | S34: 500 | U34: =S34 -> 500 | V34: 46041 | W34: =V34 -> 46041 | X34: =T34+U34 -> 500 | Y34: =S34-X34 -> 0 | Z34: CASH | AA34: =G34 -> RABONA | AB34: =IF(Y34>0,"PENDING EXECUTION","COMPLETED") -> COMPLETED | AC34: INWARDS TRANSFER | AE34: =IF(AA34=$AD$5,S34,0) -> 0 | AG34: =IF(Z34=$AG$5,X34,0) -> 500 | AH34: =IF(AA34=$AH$5,X34,0) -> 0 | AI34: EXPENSES PAID CASH YK
C35: =IF(A34=0,$C$4,"-") -> 26/1/ | D35: 20 | E35: MASTER CARD A/C | F35: IN | G35: RABONA | K35: R | L35: 46040 | M35: =L35 -> 46040 | N35: RABONA | O35: TRANSFER FROM RABONA CURRENT A/S TO RABONA MASTER CARD A/C | P35: MOVEMENT FROM CURRENT A/C TO MASTER CARD A/C | Q35: MOVEMENT FROM CURRENT A/C TO MASTER CARD A/C | S35: 60 | U35: 0 | V35: =L35 -> 46040 | W35: =V35 -> 46040 | X35: =T35+U35 -> 0 | Y35: =S35-X35 -> 60 | Z35: BT | AA35: =G35 -> RABONA | AB35: =IF(Y35>0,"PENDING EXECUTION","COMPLETED") -> PENDING EXECUTION | AC35: MOVEMENT BETWEEN A/C | AE35: =IF(AA35=$AD$5,S35,0) -> 0 | AG35: =IF(Z35=$AG$5,X35,0) -> 0 | AH35: =IF(AA35=$AH$5,X35,0) -> 0
C36: =IF(A35=0,$C$4,"-") -> 26/1/ | D36: 21 | E36: MASTER CARD A/C | F36: IN | G36: RABONA | K36: S | L36: 46041 | M36: =L36 -> 46041 | N36: RABONA | O36: TRANSFER FROM RABONA CURRENT A/S TO RABONA MASTER CARD A/C | P36: MOVEMENT FROM CURRENT A/C TO MASTER CARD A/C | Q36: MOVEMENT FROM CURRENT A/C TO MASTER CARD A/C | S36: 1500 | U36: 0 | V36: =L36 -> 46041 | W36: =V36 -> 46041 | X36: =T36+U36 -> 0 | Y36: =S36-X36 -> 1500 | Z36: BT | AA36: =G36 -> RABONA | AB36: =IF(Y36>0,"PENDING EXECUTION","COMPLETED") -> PENDING EXECUTION | AC36: MOVEMENT BETWEEN A/C | AE36: =IF(AA36=$AD$5,S36,0) -> 0 | AG36: =IF(Z36=$AG$5,X36,0) -> 0 | AH36: =IF(AA36=$AH$5,X36,0) -> 0
C37: =IF(A36=0,$C$4,"-") -> 26/1/ | D37: 22 | E37: CURRENT A/C | F37: IN | G37: RABONA | K37: T | L37: 46029 | M37: =L37 -> 46029 | N37: LUFTHANSA | O37: REFUND RECEIVED (96AAOM) | P37: OTHER (VAT RETURNS)(REFUNDS) | Q37: OTHER (VAT RETURNS)(REFUNDS) | S37: 114.32 | U37: =S37 -> 114.32 | V37: =L37 -> 46029 | W37: =V37 -> 46029 | X37: =T37+U37 -> 114.32 | Y37: =S37-X37 -> 0 | Z37: RCC | AA37: =G37 -> RABONA | AB37: =IF(Y37>0,"PENDING EXECUTION","COMPLETED") -> COMPLETED | AC37: REFUND RECEIVED | AE37: =IF(AA37=$AD$5,S37,0) -> 0 | AG37: =IF(Z37=$AG$5,X37,0) -> 0 | AH37: =IF(AA37=$AH$5,X37,0) -> 0
C38: =IF(A37=0,$C$4,"-") -> 26/1/ | D38: 23 | E38: MASTER CARD A/C | F38: IN | G38: RABONA | K38: U | L38: 46049 | M38: =L38 -> 46049 | N38: INWARDS TRANSFER FROM SHA (YORAM KEDEM) | O38: INVESTMENT FROM SHARE HOLDER | P38: BANK TRANSFERS/CASH DEPOSITS (YK) | Q38: INVESTMENT (SHARE HOLDER'S ACCOUNT) | S38: 50 | U38: =S38 -> 50 | V38: =L38 -> 46049 | W38: =V38 -> 46049 | X38: =T38+U38 -> 50 | Y38: =S38-X38 -> 0 | Z38: CASH | AA38: =G38 -> RABONA | AB38: =IF(Y38>0,"PENDING EXECUTION","COMPLETED") -> COMPLETED | AC38: INWARDS TRANSFER | AE38: =IF(AA38=$AD$5,S38,0) -> 0 | AG38: =IF(Z38=$AG$5,X38,0) -> 50 | AH38: =IF(AA38=$AH$5,X38,0) -> 0 | AI38: EXPENSES PAID CASH YK
C39: =IF(A38=0,$C$4,"-") -> 26/1/ | D39: 24 | E39: MASTER CARD A/C | F39: IN | G39: RABONA | K39: V | L39: 46052 | M39: =L39 -> 46052 | N39: INWARDS TRANSFER FROM SHA (YORAM KEDEM) | O39: INVESTMENT FROM SHARE HOLDER | P39: BANK TRANSFERS/CASH DEPOSITS (YK) | Q39: INVESTMENT (SHARE HOLDER'S ACCOUNT) | S39: 500 | U39: =S39 -> 500 | V39: =L39 -> 46052 | W39: =V39 -> 46052 | X39: =T39+U39 -> 500 | Y39: =S39-X39 -> 0 | Z39: CASH | AA39: =G39 -> RABONA | AB39: =IF(Y39>0,"PENDING EXECUTION","COMPLETED") -> COMPLETED | AC39: INWARDS TRANSFER | AE39: =IF(AA39=$AD$5,S39,0) -> 0 | AG39: =IF(Z39=$AG$5,X39,0) -> 500 | AH39: =IF(AA39=$AH$5,X39,0) -> 0 | AI39: EXPENSES PAID CASH YK
C40: =IF(A39=0,$C$4,"-") -> 26/1/ | D40: 25 | E40: MASTER CARD A/C | F40: IN | G40: RABONA | K40: W | L40: 46034 | M40: =L40 -> 46034 | N40: AEGEAN | O40: REFUND RECEIVED | P40: OTHER (VAT RETURNS)(REFUNDS) | Q40: OTHER (VAT RETURNS)(REFUNDS) | S40: 8.91 | U40: =S40 -> 8.91 | V40: =L40 -> 46034 | W40: =V40 -> 46034 | X40: =T40+U40 -> 8.91 | Y40: =S40-X40 -> 0 | Z40: RMC | AA40: =G40 -> RABONA | AB40: =IF(Y40>0,"PENDING EXECUTION","COMPLETED") -> COMPLETED | AC40: REFUND RECEIVED/MISSING SUP DOC | AE40: =IF(AA40=$AD$5,S40,0) -> 0 | AG40: =IF(Z40=$AG$5,X40,0) -> 0 | AH40: =IF(AA40=$AH$5,X40,0) -> 0
C41: =IF(A40=0,$C$4,"-") -> 26/1/ | D41: 26 | E41: MASTER CARD A/C | F41: IN | G41: RABONA | K41: Z | L41: 46034 | M41: =L41 -> 46034 | N41: AEGEAN | O41: REFUND RECEIVED | P41: OTHER (VAT RETURNS)(REFUNDS) | Q41: OTHER (VAT RETURNS)(REFUNDS) | S41: 4.79 | U41: =S41 -> 4.79 | V41: =L41 -> 46034 | W41: =V41 -> 46034 | X41: =T41+U41 -> 4.79 | Y41: =S41-X41 -> 0 | Z41: RMC | AA41: =G41 -> RABONA | AB41: =IF(Y41>0,"PENDING EXECUTION","COMPLETED") -> COMPLETED | AC41: REFUND RECEIVED/MISSING SUP DOC | AE41: =IF(AA41=$AD$5,S41,0) -> 0 | AG41: =IF(Z41=$AG$5,X41,0) -> 0 | AH41: =IF(AA41=$AH$5,X41,0) -> 0
...

Sheet EXPENSES Mothly Totals
B2: RABONA HOLDINGS LTD. | D2: JANUARY 2026
B3: MONTHLY ACTUALS
B6: REVENUE | D6: =SUM(D7:D8) -> 31829
B7: CONSULTING SERVICES | D7: =SUMIF('RABONA PAYMENTS'!$P$7:$P$206,B7,'RABONA PAYMENTS'!$X$7:$X$206) -> 29900
B8: REIMBURSMENT OF PROCURE AND RUNNING EXPENSES | D8: =SUMIF('RABONA PAYMENTS'!$P$7:$P$206,B8,'RABONA PAYMENTS'!$X$7:$X$206) -> 1929
B11: INVESTMENT (SHARE HOLDER'S ACCOUNT) | D11: =D12+D15 -> 20102.627
B12: YK | D12: =D14+D13 -> 20005.197
B13: BANK TRANSFERS/CASH DEPOSITS (YK) | D13: =SUMIF('RABONA PAYMENTS'!P7:P205,B13,'RABONA PAYMENTS'!S7:S205) -> 9500
B14: EXPENSES PAID IN CASH BY S/H (YK) | D14: =H38 -> 10505.197
B15: BK | D15: =D17+D16 -> 97.43
B16: BANK TRANSFERS/CASH DEPOSITS (BK) | D16: =SUMIF('RABONA PAYMENTS'!P7:P205,B16,'RABONA PAYMENTS'!S7:S205) -> 0
B17: EXPENSES PAID IN CASH BY S/H (BK) | D17: =H37 -> 97.43
B19: INVESTMENT (ESPARGOS) | D19: =SUMIF('RABONA PAYMENTS'!$Q$7:$Q$205,B19,'RABONA PAYMENTS'!$S$7:$S$205) -> 0
B21: OTHER (VAT RETURNS)(REFUNDS) | D21: =SUMIF('RABONA PAYMENTS'!$Q$7:$Q$205,B21,'RABONA PAYMENTS'!$S$7:$S$205) -> 128.02
B24: TOTAL REVENUE | D24: =D6+D11+D19+D21 -> 52059.647
B27: EXPENSES | D27: 44986 | F27: CHECK LIST
B29: COST OF LABOR | D29: =SUM(D30:D34) -> 2142.75 | F29: =SUMIF('RABONA PAYMENTS'!Q7:Q205,B29,'RABONA PAYMENTS'!X7:X205) -> 2142.75
B30: SALARY BK | D30: =SUMIF('RABONA PAYMENTS'!$P$7:$P$206,B30,'RABONA PAYMENTS'!$X$7:$X$206) -> 2142.75
B31: SALARY YK | D31: =SUMIF('RABONA PAYMENTS'!$P$7:$P$206,B31,'RABONA PAYMENTS'!$X$7:$X$206) -> 0
B32: Social Insurance | D32: =SUMIF('RABONA PAYMENTS'!$P$7:$P$206,B32,'RABONA PAYMENTS'!$X$7:$X$206) -> 0
B33: PAYE | D33: =SUMIF('RABONA PAYMENTS'!$P$7:$P$206,B33,'RABONA PAYMENTS'!$X$7:$X$206) -> 0
B34: INSURANCE (DAVID SHIELD) | D34: =SUMIF('RABONA PAYMENTS'!$P$7:$P$206,B34,'RABONA PAYMENTS'!$X$7:$X$206) -> 0
B36: EXPENSE REIMBURSMENT TO EMPLOYEES | D36: =SUM(D37:D38) -> 0 | F36: =SUMIF('RABONA PAYMENTS'!Q7:Q205,B36,'RABONA PAYMENTS'!X7:X205) -> 0 | H36: ='RABONA PAYMENTS'!AG206 -> 10602.627 | I36: (EXPENSES PAID IN CASH TO REFUND)
B37: EXPENSES PAID CASH BK | D37: =SUMIF('RABONA PAYMENTS'!$P$7:$P$206,B37,'RABONA PAYMENTS'!$X$7:$X$206) -> 0 | H37: =SUMIF('RABONA PAYMENTS'!$AI$7:$AI$205,B37,'RABONA PAYMENTS'!$AG$7:$AG$205) -> 97.43 | I37: INVESTMENT (BK SHARE HOLDER'S A/C)
B38: EXPENSES PAID CASH YK | D38: =SUMIF('RABONA PAYMENTS'!$P$7:$P$206,B38,'RABONA PAYMENTS'!$X$7:$X$206) -> 0 | H38: =SUMIF('RABONA PAYMENTS'!$AI$7:$AI$205,B38,'RABONA PAYMENTS'!$AG$7:$AG$205) -> 10505.197 | I38: INVESTMENT (YK SHARE HOLDER'S A/C)
B40: TAXES | D40: =SUM(D41:D46) -> 8811.59 | F40: =SUMIF('RABONA PAYMENTS'!$Q$7:$Q$205,B40,'RABONA PAYMENTS'!$X$7:$X$205) -> 8811.59
B41: GESI ON DIVIDENDS | D41: =SUMIF('RABONA PAYMENTS'!$P$7:$P$206,B41,'RABONA PAYMENTS'!$X$7:$X$206) -> 0
B42: INCOME TAX | D42: =SUMIF('RABONA PAYMENTS'!$P$7:$P$206,B42,'RABONA PAYMENTS'!$X$7:$X$206) -> 0
B43: PROVISIONAL TAX | D43: =SUMIF('RABONA PAYMENTS'!$P$7:$P$206,B43,'RABONA PAYMENTS'!$X$7:$X$206) -> 0
B44: VAT | D44: =SUMIF('RABONA PAYMENTS'!$P$7:$P$206,B44,'RABONA PAYMENTS'!$X$7:$X$206) -> 8811.59
B45: ANNUAL LEVY TO THE ROCK | D45: =SUMIF('RABONA PAYMENTS'!$P$7:$P$206,B45,'RABONA PAYMENTS'!$X$7:$X$206) -> 0
D46: =SUMIF('RABONA PAYMENTS'!$P$7:$P$206,B46,'RABONA PAYMENTS'!$X$7:$X$206) -> 0
B48: TRAVEL EXPENSES | D48: =D50+D59 -> 3506.477 | F48: =SUMIF('RABONA PAYMENTS'!$Q$7:$Q$205,B48,'RABONA PAYMENTS'!$X$7:$X$205) -> 3506.477
B50: TRAVELING ABROAD EXPENSES | D50: =SUM(D51:D57) -> 2871.137
B51: TRANSPORTATION | D51: =SUMIF('RABONA PAYMENTS'!$P$7:$P$205,B51,'RABONA PAYMENTS'!$X$7:$X$205)-D60 -> 673.27291
B52: ACCOMODATION | D52: =SUMIF('RABONA PAYMENTS'!$P$7:$P$205,B52,'RABONA PAYMENTS'!$X$7:$X$205)-D61 -> 1451.87
B53: ALLOWANCES | D53: =SUMIF('RABONA PAYMENTS'!$P$7:$P$205,B53,'RABONA PAYMENTS'!$X$7:$X$205) -> 690.74
B54: OTHER (COVID TESTS AND SPECIAL PERMITS) | D54: =SUMIF('RABONA PAYMENTS'!$P$7:$P$205,B54,'RABONA PAYMENTS'!$X$7:$X$205) -> 0
B55: MARKETING PURPOSES (HOSTING VISITS) | D55: =SUMIF('RABONA PAYMENTS'!$P$7:$P$205,B55,'RABONA PAYMENTS'!$X$7:$X$205) -> 0
B56: OTHER TRAVEL EXPENSES | D56: =SUMIF('RABONA PAYMENTS'!$P$7:$P$205,B56,'RABONA PAYMENTS'!$X$7:$X$205) -> 55.254126
...

Sheet EXP paid on behalf of Client
N1: CHECK 1 | O1: CHECK 2
N2: ='RABONA PAYMENTS'!AE206 -> 635.34 | O2: =AE28+AE56+AE113 -> 635.34 | P2: =N2-O2 -> 0
N4: REPORT MARCH 31ST 2023
B5: Ref.No. | H5: Accounting for Travel expenses | I5: Accounting for expense reimbursment | J5: salaries | L5: DATE ISSUED | N5: COMPANY | O5: ITEM | P5: SUBCATEGORY | Q5: CATEGORY | R5: TOTAL AMOUNT incl. VAT | S5: Total Amount paid (EURO) incl. VAT | V5: Date payed | W5: MONTH PAYED | X5: Total Payed incl. VAT (EURO) | Y5: Balance (EURO) | Z5: Payed buy | AA5: EXPENSE OF | AC5: Comments | AD5: REIMBURSE FROM / PRORATE TO | AE5: TOTAL AMOUNT to Prorate/Reimburse (EURO) | AF5: Invoice No. of REIMBURMENT | AG5: TOTAL AMOUNT Incl. VAT (EURO) | AI5: EXPENSES OF | AJ5: Comments
AG11: 40.04 | AH11: 0
AG12: 40.19 | AH12: 0
AG13: 110.04 | AH13: 0
AG14: 0 | AH14: 0
AG15: 0 | AH15: 0
AG16: 0 | AH16: 0
AG17: 22 | AH17: 0 | AI17: YORAM KEDEM
AG18: =IF(Z18=$AG$4,X18,0) -> 0 | AH18: =IF(AA18=$AH$4,X18,0) -> 0
AG19: =IF(Z19=$AG$4,X19,0) -> 0 | AH19: =IF(AA19=$AH$4,X19,0) -> 0
AG20: =IF(Z20=$AG$4,X20,0) -> 0 | AH20: =IF(AA20=$AH$4,X20,0) -> 0
AG21: =IF(Z21=$AG$4,X21,0) -> 0 | AH21: =IF(AA21=$AH$4,X21,0) -> 0
AG22: =IF(Z22=$AG$4,X22,0) -> 0 | AH22: =IF(AA22=$AH$4,X22,0) -> 0
AG23: =IF(Z23=$AG$4,X23,0) -> 0 | AH23: =IF(AA23=$AH$4,X23,0) -> 0
AG24: =IF(Z24=$AG$4,X24,0) -> 0 | AH24: =IF(AA24=$AH$4,X24,0) -> 0
AG25: =IF(Z25=$AG$4,X25,0) -> 0 | AH25: =IF(AA25=$AH$4,X25,0) -> 0
AG26: =IF(Z26=$AG$4,X26,0) -> 0 | AH26: =IF(AA26=$AH$4,X26,0) -> 0
AG27: =IF(Z27=$AG$4,X27,0) -> 0 | AH27: =IF(AA27=$AH$4,X27,0) -> 0 | AI27: YORAM KEDEM
O28: Inv. No: 2023/04/001 | S28: WHG | AE28: =SUM(AE6:AE9) -> 0 | AF28: Inv. No: 2021/04/016
N30: REPORT JANUARY 31ST 2025 | O30: URBAN CITY
B32: REF. NO: MONTH RECEIVED | C32: REF. NO. | E32: ACCOUNT PAID FROM | F32: INWARDS/ OUTWARDS | G32: EXPENSE OF | H32: Accounting for Travel expenses | I32: Accounting for expense reimbursment | J32: salaries | L32: DATE ISSUED | N32: COMPANY | O32: ITEM | Q32: CATEGORY | R32: TOTAL AMOUNT (foreign curancy) Incl.VAT | S32: Total Amount paid (EURO) incl. VAT | T32: AMOUNT PAID | U32: AMOUNT RECEIVED | V32: DATE PAID | W32: MONTH | X32: Total Payed incl. VAT (EURO) | Y32: Balance (EURO) | Z32: Payed buy | AA32: EXPENSE OF | AC32: Comments | AD32: REIMBURSE FROM / PRORATE TO | AE32: TOTAL AMOUNT to Reimburse (EURO) | AF32: Invoice No. of REIMBURMENT | AG32: TOTAL AMOUNT Incl. VAT (EURO) | AI32: EXPENSES OF | AJ32: Comments | AK32: EXPENSE OF RABONA
C33: 26/1/ | D33: 38 | E33: MASTER CARD A/C | F33: OUT | G33: REIMBURSE | H33: T1/8 | I33: R1/8 | L33: 46037 | M33: 46037 | N33: LARNACA INTERNATIONAL AIRPORT | O33: CAR PARKING AIRPORT | P33: TRANSPORTATION | Q33: TRAVEL EXPENSES | S33: 36 | T33: 36 | U33: 0 | V33: 46041 | W33: 46041 | X33: 36 | Y33: 0 | Z33: RMC | AA33: REIMBURSE | AB33: COMPLETED | AD33: URBAN CITY | AE33: 36 | AG33: 0 | AH33: 0
C34: 26/1/ | D34: 90 | E34: CASH | F34: OUT | G34: REIMBURSE | H34: T1/3 | I34: R1/3 | L34: 46044 | M34: 46044 | N34: POUKAKIS NICOLAS | O34: TAXI ATHENS | P34: TRANSPORTATION | Q34: TRAVEL EXPENSES | S34: 46.14 | T34: 46.14 | U34: 0 | V34: 46044 | W34: 46044 | X34: 46.14 | Y34: 0 | Z34: CASH | AA34: REIMBURSE | AB34: COMPLETED | AD34: URBAN CITY | AE34: 46.14 | AG34: 46.14 | AH34: 0 | AI34: EXPENSES PAID CASH BK
C35: 26/1/ | D35: 91 | E35: CASH | F35: OUT | G35: REIMBURSE | H35: T1/4 | I35: R1/4 | L35: 46044 | M35: 46044 | N35: POUKAKIS NICOLAS | O35: TAXI ATHENS | P35: TRANSPORTATION | Q35: TRAVEL EXPENSES | S35: 51.29 | T35: 51.29 | U35: 0 | V35: 46044 | W35: 46044 | X35: 51.29 | Y35: 0 | Z35: CASH | AA35: REIMBURSE | AB35: COMPLETED | AD35: URBAN CITY | AE35: 51.29 | AG35: 51.29 | AH35: 0 | AI35: EXPENSES PAID CASH BK
C36: 26/1/ | D36: 92 | E36: CASH | F36: OUT | G36: REIMBURSE | H36: T1/5 | I36: R1/5 | L36: 46034 | M36: 46034 | N36: POUKAKIS NICOLAS | O36: TAXI ATHENS | P36: TRANSPORTATION | Q36: TRAVEL EXPENSES | S36: 50.5 | T36: 50.5 | U36: 0 | V36: 46034 | W36: 46034 | X36: 50.5 | Y36: 0 | Z36: CASH | AA36: REIMBURSE | AB36: COMPLETED | AD36: URBAN CITY | AE36: 50.5 | AG36: 50.5 | AH36: 0 | AI36: EXPENSES PAID CASH YK
C37: 26/1/ | D37: 93 | E37: CASH | F37: OUT | G37: REIMBURSE | H37: T1/6 | I37: R1/6 | L37: 46051 | M37: 46051 | N37: POUKAKIS NICOLAS | O37: TAXI ATHENS | P37: TRANSPORTATION | Q37: TRAVEL EXPENSES | S37: 50.06 | T37: 50.06 | U37: 0 | V37: 46051 | W37: 46051 | X37: 50.06 | Y37: 0 | Z37: CASH | AA37: REIMBURSE | AB37: COMPLETED | AD37: URBAN CITY | AE37: 50.06 | AG37: 50.06 | AH37: 0 | AI37: EXPENSES PAID CASH YK
C38: 26/1/ | D38: 94 | E38: CASH | F38: OUT | G38: REIMBURSE | H38: T1/7 | I38: R1/7 | L38: 46048 | M38: 46048 | N38: POUKAKIS NICOLAS | O38: TAXI ATHENS | P38: TRANSPORTATION | Q38: TRAVEL EXPENSES | S38: 50.25 | T38: 50.25 | U38: 0 | V38: 46048 | W38: 46048 | X38: 50.25 | Y38: 0 | Z38: CASH | AA38: REIMBURSE | AB38: COMPLETED | AD38: URBAN CITY | AE38: 50.25 | AG38: 50.25 | AH38: 0 | AI38: EXPENSES PAID CASH YK
A49: T9/
C54: TOTAL TO REIMBURSE | AE54: =SUM(AE33:AE53) -> 284.24
C56: GRAND TOTAL | AE56: =SUM(AE33:AE53) -> 284.24 | AF56: Inv. No: 2021/04/017
O59: * Only 50% of the amount is to be reimburesed for flights to and from Israel
O60: ** Flights that are paid in current month but take place in fallowing month will be reimbured after the flight took place
AE62: Invoice Number | AK62: Date issued
O63: EXPENSES TO BE REIBURSED | T63: =AE54 -> 284.24
O64: MARCH EXPENSES TO BE REIBURSED IN MAY | T64: =AE55 -> 0
O65: GRAND TOTAL | T65: =SUM(T63:T64) -> 284.24
N70: REPORT JANUARY 31ST 2025 | O70: BAD Steffenstein
...

Sheet EXP to refund to employees
B2: EXPENSE REPORT MAY 31ST, 2024
B4: REF. NO: MONTH RECEIVED | C4: REF. NO: | E4: ACCOUNT PAID FROM | F4: INWARDS/ OUTWARDS | G4: EXPENSE OF | H4: Ref.No: Travel exp. | I4: Ref.No: Expense reimb. | J4: REF. NO: Salaries …. | K4: Ref.No: Inwards Transf. | L4: Document / Transfer date | M4: MONTH ISSUED | N4: COMPANY | O4: ITEM | P4: SUBCATEGORY | Q4: CATEGORY | R4: TOTAL AMOUNT (foreign curancy) Incl.VAT | S4: TOTAL AMOUNT (EURO) Incl.VAT | T4: AMOUNT PAID | U4: AMOUNT RECEIVED | V4: DATE PAID / DATE RECEIVED …. | W4: MONTH PAYED | X4: TOTAL PAID (EURO) | Y4: BALANCE (EURO) | Z4: PAYMENT TYPE …. | AA4: EXPENSE OF …. | AB4: STATUS | AC4: COMMENTS | AD4: REIMBURSE FROM/ PRORATE TO | AE4: TOTAL AMOUNT (EURO) | AF4: INVOICE NUMBER | AG4: TOTAL AMOUNT Incl. VAT (EURO) | AH4: AMOUNT | AI4: EXPENSES PAID IN CASH BY
C5: 24/5/ | D5: 32 | E5: CURRENT A/C | F5: OUT | G5: SHARE HOLDER | L5: 45422 | M5: 45422 | N5: YORAM KEDEM | O5: TRANSFER TO SHA | P5: TRANSFERS TO SH A/C AND CASH WITHDRAWAL | Q5: PERSONAL EXPENSES OF SHARE HOLDER | S5: 2000 | T5: 2000 | U5: 0 | V5: 45422 | W5: 45422 | X5: 2000 | Y5: 0 | Z5: BT | AA5: SHARE HOLDER | AB5: COMPLETED | AE5: 0 | AG5: 0 | AH5: 2000 | AI5: YORAM KEDEM
C6: 24/5/ | D6: 33 | E6: CURRENT A/C | F6: OUT | G6: SHARE HOLDER | L6: 45422 | M6: 45422 | N6: YORAM KEDEM | O6: TRANSFER TO SHA | P6: TRANSFERS TO SH A/C AND CASH WITHDRAWAL | Q6: PERSONAL EXPENSES OF SHARE HOLDER | S6: 1000 | T6: 1000 | U6: 0 | V6: 45422 | W6: 45422 | X6: 1000 | Y6: 0 | Z6: BT | AA6: SHARE HOLDER | AB6: COMPLETED | AE6: 0 | AG6: 0 | AH6: 1000 | AI6: YORAM KEDEM
C7: 24/5/ | D7: 34 | E7: CURRENT A/C | F7: OUT | G7: SHARE HOLDER | L7: 45426 | M7: 45426 | N7: YORAM KEDEM | O7: TRANSFER TO SHA | P7: TRANSFERS TO SH A/C AND CASH WITHDRAWAL | Q7: PERSONAL EXPENSES OF SHARE HOLDER | S7: 100 | T7: 100 | U7: 0 | V7: 45426 | W7: 45426 | X7: 100 | Y7: 0 | Z7: BT | AA7: SHARE HOLDER | AB7: COMPLETED | AE7: 0 | AG7: 0 | AH7: 100 | AI7: YORAM KEDEM
C8: 24/5/ | D8: 38 | E8: CURRENT A/C | F8: OUT | G8: SHARE HOLDER | L8: 45437 | M8: 45437 | N8: YORAM KEDEM | O8: TRANSFER TO SHA | P8: TRANSFERS TO SH A/C AND CASH WITHDRAWAL | Q8: PERSONAL EXPENSES OF SHARE HOLDER | S8: 100 | T8: 100 | U8: 0 | V8: 45439 | W8: 45439 | X8: 100 | Y8: 0 | Z8: BT | AA8: SHARE HOLDER | AB8: COMPLETED | AE8: 0 | AG8: 0 | AH8: 100 | AI8: YORAM KEDEM
C9: 24/5/ | D9: 39 | E9: CURRENT A/C | F9: OUT | G9: SHARE HOLDER | L9: 45441 | M9: 45441 | N9: YORAM KEDEM | O9: TRANSFER TO SHA | P9: TRANSFERS TO SH A/C AND CASH WITHDRAWAL | Q9: PERSONAL EXPENSES OF SHARE HOLDER | S9: 2000 | T9: 2000 | U9: 0 | V9: 45441 | W9: 45441 | X9: 2000 | Y9: 0 | Z9: BT | AA9: SHARE HOLDER | AB9: COMPLETED | AE9: 0 | AG9: 0 | AH9: 2000 | AI9: YORAM KEDEM
C10: 24/5/ | D10: 40 | E10: CURRENT A/C | F10: OUT | G10: SHARE HOLDER | L10: 45441 | M10: 45441 | N10: YORAM KEDEM | O10: TRANSFER TO SHA | P10: TRANSFERS TO SH A/C AND CASH WITHDRAWAL | Q10: PERSONAL EXPENSES OF SHARE HOLDER | S10: 2000 | T10: 2000 | U10: 0 | V10: 45441 | W10: 45441 | X10: 2000 | Y10: 0 | Z10: BT | AA10: SHARE HOLDER | AB10: COMPLETED | AE10: 0 | AG10: 0 | AH10: 2000 | AI10: YORAM KEDEM
C11: 24/5/ | D11: 45 | E11: MASTER CARD A/C | F11: OUT | G11: SHARE HOLDER | L11: 45439 | M11: 45439 | N11: CELLSAN | O11: PERSONAL EXPENSE OF SH | P11: PAYMENTS MADE ON BEHALF OF SH | Q11: PERSONAL EXPENSES OF SHARE HOLDER | S11: 40 | T11: 40 | U11: 0 | V11: 45439 | W11: 45439 | X11: 40 | Y11: 0 | Z11: RMC | AA11: SHARE HOLDER | AB11: COMPLETED | AE11: 0 | AG11: 0 | AH11: 40 | AI11: YORAM KEDEM
C12: 24/5/ | D12: 48 | E12: MASTER CARD A/C | F12: OUT | G12: SHARE HOLDER | L12: 45436 | M12: 45046 | N12: GINZA | O12: PERSONAL EXPENSE OF SH | P12: PAYMENTS MADE ON BEHALF OF SH | Q12: PERSONAL EXPENSES OF SHARE HOLDER | R12: 87361 | S12: 525.55 | T12: 525.55 | U12: 0 | V12: 45425 | W12: 45425 | X12: 525.55 | Y12: 0 | Z12: RMC | AA12: SHARE HOLDER | AB12: COMPLETED | AE12: 0 | AG12: 0 | AH12: 525.55 | AI12: YORAM KEDEM
C13: 24/5/ | D13: 50 | E13: MASTER CARD A/C | F13: OUT | G13: SHARE HOLDER | L13: 45425 | M13: 45425 | N13: BOLT ALION | O13: PERSONAL EXPENSE OF SH | P13: PAYMENTS MADE ON BEHALF OF SH | Q13: PERSONAL EXPENSES OF SHARE HOLDER | S13: 110.32 | T13: 110.32 | U13: 0 | V13: 45427 | W13: 45427 | X13: 110.32 | Y13: 0 | Z13: RMC | AA13: SHARE HOLDER | AB13: COMPLETED | AE13: 0 | AG13: 0 | AH13: 110.32 | AI13: YORAM KEDEM
C14: 24/5/ | D14: 51 | E14: MASTER CARD A/C | F14: OUT | G14: SHARE HOLDER | L14: 45425 | M14: 45425 | N14: BOLT TOY CONFECTIONARY | O14: PERSONAL EXPENSE OF SH | P14: PAYMENTS MADE ON BEHALF OF SH | Q14: PERSONAL EXPENSES OF SHARE HOLDER | S14: 61.19 | T14: 61.19 | U14: 0 | V14: 45427 | W14: 45427 | X14: 61.19 | Y14: 0 | Z14: RMC | AA14: SHARE HOLDER | AB14: COMPLETED | AE14: 0 | AG14: 0 | AH14: 61.19 | AI14: YORAM KEDEM
C15: 24/5/ | D15: 56 | E15: MASTER CARD A/C | F15: OUT | G15: SHARE HOLDER | L15: 45429 | M15: 45429 | N15: ALPHA MEGA | O15: PERSONAL EXPENSE OF SH | P15: PAYMENTS MADE ON BEHALF OF SH | Q15: PERSONAL EXPENSES OF SHARE HOLDER | S15: 220.13 | T15: 220.13 | U15: 0 | V15: 45429 | W15: 45429 | X15: 220.13 | Y15: 0 | Z15: RMC | AA15: SHARE HOLDER | AB15: COMPLETED | AE15: 0 | AG15: 0 | AH15: 220.13 | AI15: YORAM KEDEM
C16: 24/5/ | D16: 64 | E16: MASTER CARD A/C | F16: OUT | G16: SHARE HOLDER | L16: 45432 | M16: 45432 | N16: STIRNU BUKS | O16: PERSONAL EXPENSE OF SH | P16: PAYMENTS MADE ON BEHALF OF SH | Q16: PERSONAL EXPENSES OF SHARE HOLDER | S16: 60 | T16: 60 | U16: 0 | V16: 45432 | W16: 45432 | X16: 60 | Y16: 0 | Z16: RMC | AA16: SHARE HOLDER | AB16: COMPLETED | AE16: 0 | AG16: 0 | AH16: 60 | AI16: YORAM KEDEM
C17: 24/5/ | D17: 65 | E17: MASTER CARD A/C | F17: OUT | G17: SHARE HOLDER | L17: 45432 | M17: 45432 | N17: DUTY FREE | O17: PERSONAL EXPENSE OF SH | P17: PAYMENTS MADE ON BEHALF OF SH | Q17: PERSONAL EXPENSES OF SHARE HOLDER | S17: 46 | T17: 46 | U17: 0 | V17: 45432 | W17: 45432 | X17: 46 | Y17: 0 | Z17: RMC | AA17: SHARE HOLDER | AB17: COMPLETED | AE17: 0 | AG17: 0 | AH17: 46 | AI17: YORAM KEDEM
C18: 24/5/ | D18: 120 | E18: MASTER CARD A/C | F18: OUT | G18: SHARE HOLDER | L18: 45425 | M18: 45425 | N18: YORAM KEDEM | O18: TRANSFER TO SHA | P18: TRANSFERS TO SH A/C AND CASH WITHDRAWAL | Q18: PERSONAL EXPENSES OF SHARE HOLDER | S18: 85 | T18: 85 | U18: 0 | V18: 45425 | W18: 45425 | X18: 85 | Y18: 0 | Z18: RMC | AA18: SHARE HOLDER | AB18: COMPLETED | AE18: 0 | AG18: 0 | AH18: 85 | AI18: YORAM KEDEM
C19: 24/5/ | D19: 121 | E19: MASTER CARD A/C | F19: OUT | G19: SHARE HOLDER | L19: 45413 | M19: 45413 | N19: NIKE GINZA | O19: PERSONAL EXPENSE OF SH | P19: PAYMENTS MADE ON BEHALF OF SH | Q19: PERSONAL EXPENSES OF SHARE HOLDER | S19: 669.64 | T19: 669.64 | U19: 0 | V19: 45413 | W19: 45413 | X19: 669.64 | Y19: 0 | Z19: RMC | AA19: SHARE HOLDER | AB19: COMPLETED | AE19: 0 | AG19: 0 | AH19: 669.64 | AI19: YORAM KEDEM
C20: 24/5/ | D20: 122 | E20: MASTER CARD A/C | F20: OUT | G20: SHARE HOLDER | L20: 45415 | M20: 45415 | N20: LAWSON | O20: PERSONAL EXPENSE OF SH | P20: PAYMENTS MADE ON BEHALF OF SH | Q20: PERSONAL EXPENSES OF SHARE HOLDER | S20: 105.26 | T20: 105.26 | U20: 0 | V20: 45415 | W20: 45415 | X20: 105.26 | Y20: 0 | Z20: RMC | AA20: SHARE HOLDER | AB20: COMPLETED | AE20: 0 | AG20: 0 | AH20: 105.26 | AI20: YORAM KEDEM
C21: 24/5/ | D21: 123 | E21: MASTER CARD A/C | F21: OUT | G21: SHARE HOLDER | L21: 45425 | M21: 45425 | N21: LE CROBAG FFM | O21: PERSONAL EXPENSE OF SH | P21: PAYMENTS MADE ON BEHALF OF SH | Q21: PERSONAL EXPENSES OF SHARE HOLDER | S21: 14.4 | T21: 14.4 | U21: 0 | V21: 45425 | W21: 45425 | X21: 14.4 | Y21: 0 | Z21: RMC | AA21: SHARE HOLDER | AB21: COMPLETED | AE21: 0 | AG21: 0 | AH21: 14.4 | AI21: YORAM KEDEM
C22: 24/5/ | D22: 129 | E22: MASTER CARD A/C | F22: OUT | G22: SHARE HOLDER | L22: 45416 | M22: 45416 | N22: ORYOURI MASITA | O22: PERSONAL EXPENSE OF SH | P22: PAYMENTS MADE ON BEHALF OF SH | Q22: PERSONAL EXPENSES OF SHARE HOLDER | R22: 142.05 | S22: 866.16 | T22: 866.16 | U22: 0 | V22: 45420 | W22: 45420 | X22: 866.16 | Y22: 0 | Z22: RMC | AA22: SHARE HOLDER | AB22: COMPLETED | AE22: 0 | AG22: 0 | AH22: 866.16 | AI22: YORAM KEDEM
C23: 24/5/ | D23: 130 | E23: MASTER CARD A/C | F23: OUT | G23: SHARE HOLDER | L23: 45414 | M23: 45414 | N23: VIATORI IT | O23: PERSONAL EXPENSE OF SH | P23: PAYMENTS MADE ON BEHALF OF SH | Q23: PERSONAL EXPENSES OF SHARE HOLDER | R23: 930.26 | S23: 873.65 | T23: 873.65 | U23: 0 | V23: 45420 | W23: 45420 | X23: 873.65 | Y23: 0 | Z23: RMC | AA23: SHARE HOLDER | AB23: COMPLETED | AE23: 0 | AG23: 0 | AH23: 873.65 | AI23: YORAM KEDEM
C24: 24/5/ | D24: 131 | E24: MASTER CARD A/C | F24: OUT | G24: SHARE HOLDER | L24: 45417 | M24: 45417 | N24: VIATORI IT | O24: PERSONAL EXPENSE OF SH | P24: PAYMENTS MADE ON BEHALF OF SH | Q24: PERSONAL EXPENSES OF SHARE HOLDER | S24: 590.62 | T24: 590.62 | U24: 0 | V24: 45420 | W24: 45420 | X24: 590.62 | Y24: 0 | Z24: RMC | AA24: SHARE HOLDER | AB24: COMPLETED | AE24: 0 | AG24: 0 | AH24: 590.62 | AI24: YORAM KEDEM
C25: 24/5/ | D25: 140 | E25: MASTER CARD A/C | F25: OUT | G25: SHARE HOLDER | L25: 45443 | M25: 45443 | N25: MANTA RAY GRC | O25: PERSONAL EXPENSE OF SH | P25: PAYMENTS MADE ON BEHALF OF SH | Q25: PERSONAL EXPENSES OF SHARE HOLDER | S25: 80 | T25: 80 | U25: 0 | V25: 45443 | W25: 45443 | X25: 80 | Y25: 0 | Z25: RMC | AA25: SHARE HOLDER | AB25: COMPLETED | AE25: 0 | AG25: 0 | AH25: 80 | AI25: YORAM KEDEM
C26: 24/5/ | D26: 142 | E26: MASTER CARD A/C | F26: OUT | G26: SHARE HOLDER | L26: 45442 | M26: 45442 | N26: COLUMBIA BEACH | O26: PERSONAL EXPENSE OF SH | P26: PAYMENTS MADE ON BEHALF OF SH | Q26: PERSONAL EXPENSES OF SHARE HOLDER | S26: 129.6 | T26: 129.6 | U26: 0 | V26: 45442 | W26: 45442 | X26: 129.6 | Y26: 0 | Z26: RMC | AA26: SHARE HOLDER | AB26: COMPLETED | AC26: MISSING INVOICE/RECEIPT | AE26: 0 | AG26: 0 | AH26: 129.6 | AI26: YORAM KEDEM
B27: 23/3/66 | C27: TOTAL paid on behalf of Share Holder / transferred to Share Holders a/c (Yoram Kedem) | S27: =SUM(S5:S26) -> 11677.52
C28: 24/5/ | D28: 77 | E28: CASH PAYMENTS | F28: OUT | G28: RABONA | H28: T5/15 | L28: 45419 | M28: 45419 | N28: KAITEN SUSHI | O28: ALLOWANCES | P28: ALLOWANCES | Q28: TRAVEL EXPENSES | R28: 25030 | S28: 150.18 | T28: 150.18 | U28: 0 | V28: 45421 | W28: 45421 | X28: 150.18 | Y28: 0 | Z28: CASH | AA28: RABONA | AB28: COMPLETED | AE28: 0 | AG28: 150.18 | AH28: 0 | AI28: EXPENSES PAID CASH YK
C29: 24/5/ | D29: 78 | E29: CASH PAYMENTS | F29: OUT | G29: RABONA | H29: T5/16 | L29: 45425 | M29: 45425 | N29: ITOYA | O29: SYMBOLIC GIFT ON SIGNING | P29: MARKETING PURPOSES (HOSTING VISITS) | Q29: TRAVEL EXPENSES | R29: 47190 | S29: 278.421 | T29: 278.421 | U29: 0 | V29: 45436 | W29: 45436 | X29: 278.421 | Y29: 0 | Z29: CASH | AA29: RABONA | AB29: COMPLETED | AE29: 0 | AG29: 278.421 | AH29: 0 | AI29: EXPENSES PAID CASH YK
C30: 24/5/ | D30: 79 | E30: CASH PAYMENTS | F30: OUT | G30: RABONA | H30: T5/17 | L30: 45422 | M30: 45422 | N30: HULIC | O30: REPRESENTATION ON VISITS | P30: MARKETING PURPOSES (HOSTING VISITS) | Q30: TRAVEL EXPENSES | R30: 82280 | S30: 493.68 | T30: 493.68 | U30: 0 | V30: 45424 | W30: 45424 | X30: 493.68 | Y30: 0 | Z30: CASH | AA30: RABONA | AB30: COMPLETED | AE30: 0 | AG30: 493.68 | AH30: 0 | AI30: EXPENSES PAID CASH YK
C31: 24/5/ | D31: 80 | E31: CASH PAYMENTS | F31: OUT | G31: RABONA | H31: T5/18 | L31: 45420 | M31: 45420 | N31: LA PANZA | O31: REPRESENTATION ON VISITS | P31: MARKETING PURPOSES (HOSTING VISITS) | Q31: TRAVEL EXPENSES | R31: 52360 | S31: 308.924 | T31: 308.924 | U31: 0 | V31: 45422 | W31: 45422 | X31: 308.924 | Y31: 0 | Z31: CASH | AA31: RABONA | AB31: COMPLETED | AE31: 0 | AG31: 308.924 | AH31: 0 | AI31: EXPENSES PAID CASH YK
C32: 24/5/ | D32: 81 | E32: CASH PAYMENTS | F32: OUT | G32: RABONA | H32: T5/19 | L32: 45421 | M32: 45421 | N32: EMIT FISHBAR | O32: ALLOWANCES | P32: ALLOWANCES | Q32: TRAVEL EXPENSES | R32: 4136 | S32: 24.4024 | T32: 24.4024 | U32: 0 | V32: 45422 | W32: 45422 | X32: 24.4024 | Y32: 0 | Z32: CASH | AA32: RABONA | AB32: COMPLETED | AE32: 0 | AG32: 24.4024 | AH32: 0 | AI32: EXPENSES PAID CASH YK
C33: 24/5/ | D33: 82 | E33: CASH PAYMENTS | F33: OUT | G33: RABONA | H33: T5/20 | L33: 45421 | M33: 45421 | N33: HANAMARU NEMURO | O33: ALLOWANCES | P33: ALLOWANCES | Q33: TRAVEL EXPENSES | R33: 14421 | S33: 85.0839 | T33: 85.0839 | U33: 0 | V33: 45423 | W33: 45423 | X33: 85.0839 | Y33: 0 | Z33: CASH | AA33: RABONA | AB33: COMPLETED | AE33: 0 | AG33: 85.0839 | AH33: 0 | AI33: EXPENSES PAID CASH YK
C34: 24/5/ | D34: 83 | E34: CASH PAYMENTS | F34: OUT | G34: RABONA | H34: T5/21 | L34: 45417 | M34: 45417 | N34: DINING BAR W | O34: ALLOWANCES | P34: ALLOWANCES | Q34: TRAVEL EXPENSES | R34: 8873 | S34: 53.238 | T34: 53.238 | U34: 0 | V34: 45420 | W34: 45420 | X34: 53.238 | Y34: 0 | Z34: CASH | AA34: RABONA | AB34: COMPLETED | AE34: 0 | AG34: 53.238 | AH34: 0 | AI34: EXPENSES PAID CASH YK
C35: 24/5/ | D35: 84 | E35: CASH PAYMENTS | F35: OUT | G35: RABONA | H35: T5/22 | L35: 45419 | M35: 45419 | N35: STARBACKS | O35: ALLOWANCES | P35: ALLOWANCES | Q35: TRAVEL EXPENSES | R35: 4706 | S35: 28.236 | T35: 28.236 | U35: 0 | V35: 45419 | W35: 45419 | X35: 28.236 | Y35: 0 | Z35: CASH | AA35: RABONA | AB35: COMPLETED | AE35: 0 | AG35: 28.236 | AH35: 0 | AI35: EXPENSES PAID CASH YK
C36: 24/5/ | D36: 85 | E36: CASH PAYMENTS | F36: OUT | G36: RABONA | H36: T5/23 | L36: 45415 | M36: 45415 | N36: CUCINA ITALIANA | O36: REPRESENTATION ON VISITS | P36: MARKETING PURPOSES (HOSTING VISITS) | Q36: TRAVEL EXPENSES | R36: 67100 | S36: 409.31 | T36: 409.31 | U36: 0 | V36: 45415 | W36: 45415 | X36: 409.31 | Y36: 0 | Z36: CASH | AA36: RABONA | AB36: COMPLETED | AE36: 0 | AG36: 409.31 | AH36: 0 | AI36: EXPENSES PAID CASH YK
C37: 24/5/ | D37: 86 | E37: CASH PAYMENTS | F37: OUT | G37: RABONA | H37: T5/24 | L37: 45417 | M37: 45417 | N37: KANI GORAKU | O37: REPRESENTATION ON VISITS | P37: MARKETING PURPOSES (HOSTING VISITS) | Q37: TRAVEL EXPENSES | R37: 71412 | S37: 428.472 | T37: 428.472 | U37: 0 | V37: 45417 | W37: 45417 | X37: 428.472 | Y37: 0 | Z37: CASH | AA37: RABONA | AB37: COMPLETED | AE37: 0 | AG37: 428.472 | AH37: 0 | AI37: EXPENSES PAID CASH YK
C38: 24/5/ | D38: 87 | E38: CASH PAYMENTS | F38: OUT | G38: RABONA | H38: T5/25 | L38: 45418 | M38: 45418 | N38: NEW JAPAN TOURIST CO. LTD | O38: TAXI JAPAN | P38: TRANSPORTATION | Q38: TRAVEL EXPENSES | R38: 5380 | S38: 32.28 | T38: 32.28 | U38: 0 | V38: 45418 | W38: 45418 | X38: 32.28 | Y38: 0 | Z38: CASH | AA38: RABONA | AB38: COMPLETED | AE38: 0 | AG38: 32.28 | AH38: 0 | AI38: EXPENSES PAID CASH YK
C39: 24/5/ | D39: 88 | E39: CASH PAYMENTS | F39: OUT | G39: RABONA | H39: T5/26 | L39: 45419 | M39: 45419 | N39: GYUKATSUMOTOMURA | O39: ALLOWANCES | P39: ALLOWANCES | Q39: TRAVEL EXPENSES | R39: 10890 | S39: 65.34 | T39: 65.34 | U39: 0 | V39: 45419 | W39: 45419 | X39: 65.34 | Y39: 0 | Z39: CASH | AA39: RABONA | AB39: COMPLETED | AE39: 0 | AG39: 65.34 | AH39: 0 | AI39: EXPENSES PAID CASH YK
... C50: 24/5/ | D50: 99 | E50: CASH PAYMENTS | F50: OUT | G50: RABONA | H50: T5/37 | L50: 45417 | M50: 45417 | N50: UBER | O50: TAXI JAPAN | P50: TRANSPORTATION | Q50: TRAVEL EXPENSES | R50: 6217 | S50: 37.302 | T50: 37.302 | U50: 0 | V50: 45417 | W50: 45417 | X50: 37.302 | Y50: 0 | Z50: CASH | AA50: RABONA | AB50: COMPLETED | AE50: 0 | AG50: 37.302 | AH50: 0 | AI50: EXPENSES PAID CASH YK
C51: 24/5/ | D51: 100 | E51: CASH PAYMENTS | F51: OUT | G51: RABONA | H51: T5/1 | L51: 45399 | M51: 45399 | N51: ELDAN | O51: CAR RENT IL | P51: TRANSPORTATION | Q51: TRAVEL EXPENSES | S51: 778.31 | T51: 778.31 | U51: 0 | V51: 45399 | W51: 45399 | X51: 778.31 | Y51: 0 | Z51: CASH | AA51: RABONA | AB51: COMPLETED | AE51: 0 | AG51: 778.31 | AH51: 0 | AI51: EXPENSES PAID CASH YK
C52: 24/5/ | D52: 101 | E52: CASH PAYMENTS | F52: OUT | G52: RABONA | H52: T5/38 | L52: 45416 | M52: 45416 | N52: UBER | O52: TAXI JAPAN | P52: TRANSPORTATION | Q52: TRAVEL EXPENSES | R52: 8701 | S52: 52.206 | T52: 52.206 | U52: 0 | V52: 45416 | W52: 45416 | X52: 52.206 | Y52: 0 | Z52: CASH | AA52: RABONA | AB52: COMPLETED | AE52: 0 | AG52: 52.206 | AH52: 0 | AI52: EXPENSES PAID CASH YK
...
